Workbook

Sheet Import Report Template
A1: Formal Entry Number | B1: Line No | C1: Importer Name | D1: EORI Number / Tax ID / Equivalent | E1: Arrival Date | F1: Entry Date (ddmmyy) | G1: Port of Entry | H1: Declaration Country | I1: Country of Origin | J1: Shipping Country | K1: HTS Code (Tariff Number) | L1: Item Description | M1: Invoice value | N1: Invoice Number | O1: Invoice currency | P1: Exchange Rate | Q1: Declared Value | R1: Customs Value currency | S1: Duty Paid | T1: Duty Rate % | U1: VAT Value | V1: VAT Paid | W1: VAT Rate % | X1: Other Fees / Taxes | Y1: Anti Dumping / Countervailing Duties | Z1: Special Trade Program (e.g. FTA) | AA1: Supplier Name / Shipper Name | AB1: Custom broker company name | AC1: Transport Mode | AD1: Incoterms | AE1: Customs Quantity | AF1: Unit of measurement | AG1: Net Mass (in kg) | AH1: Gross Mass (in kg) | AI1: Entry Type | AJ1: Branch | AK1: Site Name | AL1: Site Number | AM1: Broker Reference Number | AN1: AWB / Bill Of Lading | AO1: CBAM related goods ? Y/N | AP1: CBAM goods category * | AQ1: CBAM Exeption applied ? Y/N | AR1: CBAM Type of exeption
A2: ='Input AC Report '!BL2 -> ATC400014140420253302/00001 | B2: ='Input AC Report '!G2 -> 1 | C2: ='Input AC Report '!GO2 -> DE2393166-0000,HELLA GMBH & CO. KGAAUST | D2: =LEFT(C2,9) -> DE2393166 | E2: =_xlfn.IFNA(VLOOKUP('Input AC Report '!DU2,Validation!A:B,2,FALSE),"") | F2: =_xlfn.IFNA(VLOOKUP('Input AC Report '!EQ2,Validation!A:B,2,FALSE),"") | G2: FRA | H2: =LEFT('Input AC Report '!I2,2) -> DE | I2: ='Input AC Report '!AS2 -> MX | J2: ='Input AC Report '!AR2 -> MX | K2: ='Input AC Report '!O2 -> 85371098990 | L2: ='Input AC Report '!N2 -> STEUERGERÄT für Autoscheinwerfer | M2: ='Input AC Report '!AB2 -> 87121.92 | N2: ='Input AC Report '!W2 -> 84B9655A-FD8D-40F18489-FA85119561CF | O2: ='Input AC Report '!AD2 -> USD | P2: ='Input AC Report '!AE2 -> 1.0897 | Q2: ='Input AC Report '!AH2 -> 79913.23 | R2: ='Input AC Report '!AG2 -> USD | S2: ='Input AC Report '!AP2 -> 1678.18 | T2: ='Input AC Report '!AJ2 -> 2.1 | U2: ='Input AC Report '!AN2 -> 81752.47 | V2: ='Input AC Report '!AO2 -> 15532.97 | W2: 19 | AA2: ='Input AC Report '!CI2 -> SIIX EMS MEXICO S. DE R.L. DE C.V.,San Luis Potosí | AB2: ='Input AC Report '!GX2 -> DE2329875-0024,DSV Air & Sea Germany GmbH - Westerkappeln | AC2: =_xlfn.IFNA(VLOOKUP('Input AC Report '!CU2,Validation!G:J,2,FALSE),"") -> Air | AD2: ='Input AC Report '!X2 -> DAP | AE2: ='Input AC Report '!V2 -> 2 | AF2: ='Input AC Report '!U2 -> PK | AG2: ='Input AC Report '!S2 -> 385 | AH2: ='Input AC Report '!T2 -> 405 | AI2: =_xlfn.IFNA(VLOOKUP('Input AC Report '!J2,Validation!J:K,2,FALSE),"") -> permanent import | AJ2: =MID('Input AC Report '!GX2,45,30) -> Westerkappeln | AK2: =MID('Input AC Report '!GP2,12,35) -> 000,HELLA GMBH & CO. KGAAUST | AM2: ='Input AC Report '!A2 -> SQRO0045723 | AN2: ='Input AC Report '!A2 -> SQRO0045723
A3: ='Input AC Report '!BL3 -> ATC400001020420253306/00001 | B3: ='Input AC Report '!G3 -> 1 | C3: ='Input AC Report '!GO3 -> DE4529340,HELLA Innenleuchten-Systeme GmbH | D3: =LEFT(C3,9) -> DE4529340 | E3: =_xlfn.IFNA(VLOOKUP('Input AC Report '!DU3,Validation!A:B,2,FALSE),"") | F3: =_xlfn.IFNA(VLOOKUP('Input AC Report '!EQ3,Validation!A:B,2,FALSE),"") | G3: FRA | H3: =LEFT('Input AC Report '!I3,2) -> DE | I3: ='Input AC Report '!AS3 -> CN | J3: ='Input AC Report '!AR3 -> HK | K3: ='Input AC Report '!O3 -> 85340011000 | L3: ='Input AC Report '!N3 -> Gedruckte Schaltungen,hier: Mehrlagenschaltungen / Leiterplatten | M3: ='Input AC Report '!AB3 -> 3773.39 | N3: ='Input AC Report '!W3 -> NL25040106 | O3: ='Input AC Report '!AD3 -> EUR | P3: ='Input AC Report '!AE3 -> 1 | Q3: ='Input AC Report '!AH3 -> 1943.39 | R3: ='Input AC Report '!AG3 -> EUR | S3: ='Input AC Report '!AP3 -> 0 | T3: ='Input AC Report '!AJ3 -> 0 | U3: ='Input AC Report '!AN3 -> 3773.39 | V3: ='Input AC Report '!AO3 -> 716.94 | W3: 19 | AA3: ='Input AC Report '!CI3 -> Rayben Technologies (HK) Limited,Shatin, Hong Kong | AB3: ='Input AC Report '!GX3 -> DE2329875-0024,DSV Air & Sea Germany GmbH - Westerkappeln | AC3: =_xlfn.IFNA(VLOOKUP('Input AC Report '!CU3,Validation!G:J,2,FALSE),"") -> Air | AD3: ='Input AC Report '!X3 -> DAP | AE3: ='Input AC Report '!V3 -> 8 | AF3: ='Input AC Report '!U3 -> PK | AG3: ='Input AC Report '!S3 -> 118.2 | AH3: ='Input AC Report '!T3 -> 126.2 | AI3: =_xlfn.IFNA(VLOOKUP('Input AC Report '!J3,Validation!J:K,2,FALSE),"") -> permanent import | AJ3: =MID('Input AC Report '!GX3,45,30) -> Westerkappeln | AK3: =MID('Input AC Report '!GP3,12,35) -> HELLA Innenleuchten-Systeme GmbH | AM3: ='Input AC Report '!A3 -> SZSN7076556 | AN3: ='Input AC Report '!A3 -> SZSN7076556
A4: ='Input AC Report '!BL4 -> ATC400215310420253302/00001 | B4: ='Input AC Report '!G4 -> 1 | C4: ='Input AC Report '!GO4 -> DE4529340,HELLA Innenleuchten-Systeme GmbH | D4: =LEFT(C4,9) -> DE4529340 | E4: =_xlfn.IFNA(VLOOKUP('Input AC Report '!DU4,Validation!A:B,2,FALSE),"") | F4: =_xlfn.IFNA(VLOOKUP('Input AC Report '!EQ4,Validation!A:B,2,FALSE),"") | G4: =_xlfn.IFNA(VLOOKUP('Input AC Report '!I4,Validation!D:E,2,FALSE),"") -> FRA | H4: =LEFT('Input AC Report '!I4,2) -> DE | I4: ='Input AC Report '!AS4 -> CN | J4: ='Input AC Report '!AR4 -> HK | K4: ='Input AC Report '!O4 -> 85340011000 | L4: ='Input AC Report '!N4 -> Mehrlagenschaltungen / Leiterplatten | M4: ='Input AC Report '!AB4 -> 4322.88 | N4: ='Input AC Report '!W4 -> HK132425040005 HK132425040006 | O4: ='Input AC Report '!AD4 -> EUR | P4: ='Input AC Report '!AE4 -> 1 | Q4: ='Input AC Report '!AH4 -> 6138.12 | R4: ='Input AC Report '!AG4 -> EUR | S4: ='Input AC Report '!AP4 -> 0 | T4: ='Input AC Report '!AJ4 -> 0 | U4: ='Input AC Report '!AN4 -> 6761.91 | V4: ='Input AC Report '!AO4 -> 1284.76 | W4: 19 | AA4: ='Input AC Report '!CI4 -> KINWONG ELECTRONIC (HONG KONG) LIMITED,Tsuen Fanli | AB4: ='Input AC Report '!GX4 -> DE2329875-0024,DSV Air & Sea Germany GmbH - Westerkappeln | AC4: =_xlfn.IFNA(VLOOKUP('Input AC Report '!CU4,Validation!G:J,2,FALSE),"") -> Air | AD4: ='Input AC Report '!X4 -> EXW | AE4: ='Input AC Report '!V4 -> 1 | AF4: ='Input AC Report '!U4 -> PK | AG4: ='Input AC Report '!S4 -> 165.4 | AH4: ='Input AC Report '!T4 -> 174 | AI4: =_xlfn.IFNA(VLOOKUP('Input AC Report '!J4,Validation!J:K,2,FALSE),"") -> permanent import | AJ4: =MID('Input AC Report '!GX4,45,30) -> Westerkappeln | AK4: =MID('Input AC Report '!GP4,12,35) -> HELLA Innenleuchten-Systeme GmbH | AM4: ='Input AC Report '!A4 -> SHKG1308921-A | AN4: ='Input AC Report '!A4 -> SHKG1308921-A
A5: ='Input AC Report '!BL5 -> ATC400256830420253302/00001 | B5: ='Input AC Report '!G5 -> 1 | C5: ='Input AC Report '!GO5 -> DE2393166-0000,HELLA GMBH & CO. KGAAUST | D5: =LEFT(C5,9) -> DE2393166 | E5: =_xlfn.IFNA(VLOOKUP('Input AC Report '!DU5,Validation!A:B,2,FALSE),"") | F5: =_xlfn.IFNA(VLOOKUP('Input AC Report '!EQ5,Validation!A:B,2,FALSE),"") | G5: =_xlfn.IFNA(VLOOKUP('Input AC Report '!I5,Validation!D:E,2,FALSE),"") -> FRA | H5: =LEFT('Input AC Report '!I5,2) -> DE | I5: ='Input AC Report '!AS5 -> MX | J5: ='Input AC Report '!AR5 -> MX | K5: ='Input AC Report '!O5 -> 85371098990 | L5: ='Input AC Report '!N5 -> STEUERGERÄT für Autoscheinwerfer | M5: ='Input AC Report '!AB5 -> 130682.88 | N5: ='Input AC Report '!W5 -> 41084651-A125-460392E4-A3803D2D4423 | O5: ='Input AC Report '!AD5 -> USD | P5: ='Input AC Report '!AE5 -> 1.0897 | Q5: ='Input AC Report '!AH5 -> 119905.59 | R5: ='Input AC Report '!AG5 -> USD | S5: ='Input AC Report '!AP5 -> 2518.02 | T5: ='Input AC Report '!AJ5 -> 2.1 | U5: ='Input AC Report '!AN5 -> 122629.47 | V5: ='Input AC Report '!AO5 -> 23299.6 | W5: 19 | AA5: ='Input AC Report '!CI5 -> SIIX EMS MEXICO S. DE R.L. DE C.V.,San Luis Potosí | AB5: ='Input AC Report '!GX5 -> DE2329875-0024,DSV Air & Sea Germany GmbH - Westerkappeln | AC5: =_xlfn.IFNA(VLOOKUP('Input AC Report '!CU5,Validation!G:J,2,FALSE),"") -> Air | AD5: ='Input AC Report '!X5 -> DAP | AE5: ='Input AC Report '!V5 -> 3 | AF5: ='Input AC Report '!U5 -> PK | AG5: ='Input AC Report '!S5 -> 560 | AH5: ='Input AC Report '!T5 -> 590.3 | AI5: =_xlfn.IFNA(VLOOKUP('Input AC Report '!J5,Validation!J:K,2,FALSE),"") -> permanent import | AJ5: =MID('Input AC Report '!GX5,45,30) -> Westerkappeln | AK5: =MID('Input AC Report '!GP5,12,35) -> 000,HELLA GMBH & CO. KGAAUST | AM5: ='Input AC Report '!A5 -> SQRO0045994 | AN5: ='Input AC Report '!A5 -> SQRO0045994
A6: ='Input AC Report '!BL6 -> ATC400258470420253302/00001 | B6: ='Input AC Report '!G6 -> 1 | C6: ='Input AC Report '!GO6 -> DE4529340,HELLA Innenleuchten-Systeme GmbH | D6: =LEFT(C6,9) -> DE4529340 | E6: =_xlfn.IFNA(VLOOKUP('Input AC Report '!DU6,Validation!A:B,2,FALSE),"") | F6: =_xlfn.IFNA(VLOOKUP('Input AC Report '!EQ6,Validation!A:B,2,FALSE),"") | G6: =_xlfn.IFNA(VLOOKUP('Input AC Report '!I6,Validation!D:E,2,FALSE),"") -> FRA | H6: =LEFT('Input AC Report '!I6,2) -> DE | I6: ='Input AC Report '!AS6 -> CN | J6: ='Input AC Report '!AR6 -> HK | K6: ='Input AC Report '!O6 -> 85340011000 | L6: ='Input AC Report '!N6 -> Gedruckte Schaltungen,hier: Mehrlagenschaltungen / Leiterplatten | M6: ='Input AC Report '!AB6 -> 14361.14 | N6: ='Input AC Report '!W6 -> NL25040232 NL25040233 NL25040234 | O6: ='Input AC Report '!AD6 -> EUR | P6: ='Input AC Report '!AE6 -> 1 | Q6: ='Input AC Report '!AH6 -> 14057.37 | R6: ='Input AC Report '!AG6 -> EUR | S6: ='Input AC Report '!AP6 -> 0 | T6: ='Input AC Report '!AJ6 -> 0 | U6: ='Input AC Report '!AN6 -> 14775.52 | V6: ='Input AC Report '!AO6 -> 2807.35 | W6: 19 | AA6: ='Input AC Report '!CI6 -> Rayben Technologies (HK) Limited,Shatin, Hong Kong | AB6: ='Input AC Report '!GX6 -> DE2329875-0024,DSV Air & Sea Germany GmbH - Westerkappeln | AC6: =_xlfn.IFNA(VLOOKUP('Input AC Report '!CU6,Validation!G:J,2,FALSE),"") -> Air | AD6: ='Input AC Report '!X6 -> FCA | AE6: ='Input AC Report '!V6 -> 1 | AF6: ='Input AC Report '!U6 -> PK | AG6: ='Input AC Report '!S6 -> 438.5 | AH6: ='Input AC Report '!T6 -> 474 | AI6: =_xlfn.IFNA(VLOOKUP('Input AC Report '!J6,Validation!J:K,2,FALSE),"") -> permanent import | AJ6: =MID('Input AC Report '!GX6,45,30) -> Westerkappeln | AK6: =MID('Input AC Report '!GP6,12,35) -> HELLA Innenleuchten-Systeme GmbH | AM6: ='Input AC Report '!A6 -> SZSN7076620 | AN6: ='Input AC Report '!A6 -> SZSN7076620
A7: ='Input AC Report '!BL7 -> ATC400392280420253302/00001 | B7: ='Input AC Report '!G7 -> 1 | C7: ='Input AC Report '!GO7 -> DE2393166-0000,HELLA GMBH & CO. KGAAUST | D7: =LEFT(C7,9) -> DE2393166 | E7: =_xlfn.IFNA(VLOOKUP('Input AC Report '!DU7,Validation!A:B,2,FALSE),"") | F7: =_xlfn.IFNA(VLOOKUP('Input AC Report '!EQ7,Validation!A:B,2,FALSE),"") | G7: FRA | H7: =LEFT('Input AC Report '!I7,2) -> DE | I7: ='Input AC Report '!AS7 -> CN | J7: ='Input AC Report '!AR7 -> HK | K7: ='Input AC Report '!O7 -> 85340011000 | L7: ='Input AC Report '!N7 -> Gedruckte Schaltungen - nur mit Leiterbahnen oder Kontakten,hier: Mehrlagenschaltungen | M7: ='Input AC Report '!AB7 -> 1806.94 | N7: ='Input AC Report '!W7 -> TC58596-3D04I | O7: ='Input AC Report '!AD7 -> EUR | P7: ='Input AC Report '!AE7 -> 1 | Q7: ='Input AC Report '!AH7 -> 1986 | R7: ='Input AC Report '!AG7 -> EUR | S7: ='Input AC Report '!AP7 -> 0 | T7: ='Input AC Report '!AJ7 -> 0 | U7: ='Input AC Report '!AN7 -> 2061.54 | V7: ='Input AC Report '!AO7 -> 391.69 | W7: 19 | AA7: ='Input AC Report '!CI7 -> TECHWISE(MACAO)CIRCUITS Ltd.,Macau,00000,Da praia | AB7: ='Input AC Report '!GX7 -> DE2329875-0024,DSV Air & Sea Germany GmbH - Westerkappeln | AC7: =_xlfn.IFNA(VLOOKUP('Input AC Report '!CU7,Validation!G:J,2,FALSE),"") -> Air | AD7: ='Input AC Report '!X7 -> FOB | AE7: ='Input AC Report '!V7 -> 5 | AF7: ='Input AC Report '!U7 -> PK | AG7: ='Input AC Report '!S7 -> 40 | AH7: ='Input AC Report '!T7 -> 43 | AI7: =_xlfn.IFNA(VLOOKUP('Input AC Report '!J7,Validation!J:K,2,FALSE),"") -> permanent import | AJ7: =MID('Input AC Report '!GX7,45,30) -> Westerkappeln | AK7: =MID('Input AC Report '!GP7,12,35) -> 000,HELLA GMBH & CO. KGAAUST | AM7: ='Input AC Report '!A7 -> SHKG1311544 | AN7: ='Input AC Report '!A7 -> SHKG1311544
A8: ='Input AC Report '!BL8 -> ATC400405280420253302/00001 | B8: ='Input AC Report '!G8 -> 1 | C8: ='Input AC Report '!GO8 -> DE2393166-0000,HELLA GMBH & CO. KGAAUST | D8: =LEFT(C8,9) -> DE2393166 | E8: =_xlfn.IFNA(VLOOKUP('Input AC Report '!DU8,Validation!A:B,2,FALSE),"") | F8: =_xlfn.IFNA(VLOOKUP('Input AC Report '!EQ8,Validation!A:B,2,FALSE),"") | G8: =_xlfn.IFNA(VLOOKUP('Input AC Report '!I8,Validation!D:E,2,FALSE),"") -> FRA | H8: =LEFT('Input AC Report '!I8,2) -> DE | I8: ='Input AC Report '!AS8 -> CN | J8: ='Input AC Report '!AR8 -> CN | K8: ='Input AC Report '!O8 -> 85340011000 | L8: ='Input AC Report '!N8 -> Gedruckte Schaltungen - nur mit Leiterbahnen oder Kontakten,hier: Mehrlagenschaltungen | M8: ='Input AC Report '!AB8 -> 9612.84 | N8: ='Input AC Report '!W8 -> KW12102504170001 | O8: ='Input AC Report '!AD8 -> EUR | P8: ='Input AC Report '!AE8 -> 1 | Q8: ='Input AC Report '!AH8 -> 10821.43 | R8: ='Input AC Report '!AG8 -> EUR | S8: ='Input AC Report '!AP8 -> 0 | T8: ='Input AC Report '!AJ8 -> 0 | U8: ='Input AC Report '!AN8 -> 11164.29 | V8: ='Input AC Report '!AO8 -> 2121.22 | W8: 19 | AA8: ='Input AC Report '!CI8 -> KINWONG ELECTRONIC(HONGKONG) LIMITED,HONG KONG,000 | AB8: ='Input AC Report '!GX8 -> DE2329875-0024,DSV Air & Sea Germany GmbH - Westerkappeln | AC8: =_xlfn.IFNA(VLOOKUP('Input AC Report '!CU8,Validation!G:J,2,FALSE),"") -> Air | AD8: ='Input AC Report '!X8 -> EXW | AE8: ='Input AC Report '!V8 -> 1 | AF8: ='Input AC Report '!U8 -> PK | AG8: ='Input AC Report '!S8 -> 213.2 | AH8: ='Input AC Report '!T8 -> 250 | AI8: =_xlfn.IFNA(VLOOKUP('Input AC Report '!J8,Validation!J:K,2,FALSE),"") -> permanent import | AJ8: =MID('Input AC Report '!GX8,45,30) -> Westerkappeln | AK8: =MID('Input AC Report '!GP8,12,35) -> 000,HELLA GMBH & CO. KGAAUST | AM8: ='Input AC Report '!A8 -> SSZX71000388 | AN8: ='Input AC Report '!A8 -> SSZX71000388
A9: ='Input AC Report '!BL9 -> ATC400415190420253302/00001 | B9: ='Input AC Report '!G9 -> 1 | C9: ='Input AC Report '!GO9 -> DE2393166-0000,HELLA GMBH & CO. KGAAUST | D9: =LEFT(C9,9) -> DE2393166 | E9: =_xlfn.IFNA(VLOOKUP('Input AC Report '!DU9,Validation!A:B,2,FALSE),"") | F9: =_xlfn.IFNA(VLOOKUP('Input AC Report '!EQ9,Validation!A:B,2,FALSE),"") | G9: =_xlfn.IFNA(VLOOKUP('Input AC Report '!I9,Validation!D:E,2,FALSE),"") -> FRA | H9: =LEFT('Input AC Report '!I9,2) -> DE | I9: ='Input AC Report '!AS9 -> TH | J9: ='Input AC Report '!AR9 -> TH | K9: ='Input AC Report '!O9 -> 84145925900 | L9: ='Input AC Report '!N9 -> Axialventilator | M9: ='Input AC Report '!AB9 -> 28684.8 | N9: ='Input AC Report '!W9 -> 9404416357 | O9: ='Input AC Report '!AD9 -> USD | P9: ='Input AC Report '!AE9 -> 1.0897 | Q9: ='Input AC Report '!AH9 -> 27891.59 | R9: ='Input AC Report '!AG9 -> EUR | S9: ='Input AC Report '!AP9 -> 641.51 | T9: ='Input AC Report '!AJ9 -> 2.3 | U9: ='Input AC Report '!AN9 -> 29129.33 | V9: ='Input AC Report '!AO9 -> 5534.57 | W9: 19 | AA9: ='Input AC Report '!CI9 -> DELTA ELECTRONICS(THAILAND)PUBLIC COMPANY LIMITED, | AB9: ='Input AC Report '!GX9 -> DE2329875-0024,DSV Air & Sea Germany GmbH - Westerkappeln | AC9: =_xlfn.IFNA(VLOOKUP('Input AC Report '!CU9,Validation!G:J,2,FALSE),"") -> Air | AD9: ='Input AC Report '!X9 -> FCA | AE9: ='Input AC Report '!V9 -> 1 | AF9: ='Input AC Report '!U9 -> PK | AG9: ='Input AC Report '!S9 -> 241.9 | AH9: ='Input AC Report '!T9 -> 338 | AI9: =_xlfn.IFNA(VLOOKUP('Input AC Report '!J9,Validation!J:K,2,FALSE),"") -> permanent import | AJ9: =MID('Input AC Report '!GX9,45,30) -> Westerkappeln | AK9: =MID('Input AC Report '!GP9,12,35) -> 000,HELLA GMBH & CO. KGAAUST | AM9: ='Input AC Report '!A9 -> SSPK0264878 | AN9: ='Input AC Report '!A9 -> SSPK0264878
A10: ='Input AC Report '!BL10 -> ATC400055070520253302/00001 | B10: ='Input AC Report '!G10 -> 1 | C10: ='Input AC Report '!GO10 -> DE2393166-0000,HELLA GMBH & CO. KGAAUST | D10: =LEFT(C10,9) -> DE2393166 | E10: =_xlfn.IFNA(VLOOKUP('Input AC Report '!DU10,Validation!A:B,2,FALSE),"") | F10: =_xlfn.IFNA(VLOOKUP('Input AC Report '!EQ10,Validation!A:B,2,FALSE),"") | G10: =_xlfn.IFNA(VLOOKUP('Input AC Report '!I10,Validation!D:E,2,FALSE),"") -> FRA | H10: =LEFT('Input AC Report '!I10,2) -> DE | I10: ='Input AC Report '!AS10 -> VN | J10: ='Input AC Report '!AR10 -> VN | K10: ='Input AC Report '!O10 -> 85371098990 | L10: ='Input AC Report '!N10 -> Elektronisches Steuergerät für Kfz-Scheinwerfer | M10: ='Input AC Report '!AB10 -> 100543.68 | N10: ='Input AC Report '!W10 -> UHAN_INV05870 | O10: ='Input AC Report '!AD10 -> USD | P10: ='Input AC Report '!AE10 -> 1.1415 | Q10: ='Input AC Report '!AH10 -> 91037.69 | R10: ='Input AC Report '!AG10 -> USD | S10: ='Input AC Report '!AP10 -> 1911.79 | T10: ='Input AC Report '!AJ10 -> 2.1 | U10: ='Input AC Report '!AN10 -> 94158.42 | V10: ='Input AC Report '!AO10 -> 17890.1 | W10: 19 | AA10: ='Input AC Report '!CI10 -> UNIGEN CORPORATION,Newark,CA,94560,39730 Eureka Dr | AB10: ='Input AC Report '!GX10 -> DE2329875-0024,DSV Air & Sea Germany GmbH - Westerkappeln | AC10: =_xlfn.IFNA(VLOOKUP('Input AC Report '!CU10,Validation!G:J,2,FALSE),"") -> Air | AD10: ='Input AC Report '!X10 -> FCA | AE10: ='Input AC Report '!V10 -> 3 | AF10: ='Input AC Report '!U10 -> PK | AG10: ='Input AC Report '!S10 -> 510 | AH10: ='Input AC Report '!T10 -> 535 | AI10: =_xlfn.IFNA(VLOOKUP('Input AC Report '!J10,Validation!J:K,2,FALSE),"") -> permanent import | AJ10: =MID('Input AC Report '!GX10,45,30) -> Westerkappeln | AK10: =MID('Input AC Report '!GP10,12,35) -> 000,HELLA GMBH & CO. KGAAUST | AM10: ='Input AC Report '!A10 -> SHAN0394305 | AN10: ='Input AC Report '!A10 -> SHAN0394305
A11: ='Input AC Report '!BL11 -> ATC400065720520253302/00001 | B11: ='Input AC Report '!G11 -> 1 | C11: ='Input AC Report '!GO11 -> DE2393166-0000,HELLA GMBH & CO. KGAAUST | D11: =LEFT(C11,9) -> DE2393166 | E11: =_xlfn.IFNA(VLOOKUP('Input AC Report '!DU11,Validation!A:B,2,FALSE),"") | F11: =_xlfn.IFNA(VLOOKUP('Input AC Report '!EQ11,Validation!A:B,2,FALSE),"") | G11: =_xlfn.IFNA(VLOOKUP('Input AC Report '!I11,Validation!D:E,2,FALSE),"") -> FRA | H11: =LEFT('Input AC Report '!I11,2) -> DE | I11: ='Input AC Report '!AS11 -> MX | J11: ='Input AC Report '!AR11 -> MX | K11: ='Input AC Report '!O11 -> 85371098990 | L11: ='Input AC Report '!N11 -> STEUERGERÄT für Autoscheinwerfer | M11: ='Input AC Report '!AB11 -> 4537.6 | N11: ='Input AC Report '!W11 -> 4FF9AA4C-4710-4232-8489FD25BA77EB19 | O11: ='Input AC Report '!AD11 -> USD | P11: ='Input AC Report '!AE11 -> 1.1415 | Q11: ='Input AC Report '!AH11 -> 3931.72 | R11: ='Input AC Report '!AG11 -> USD | S11: ='Input AC Report '!AP11 -> 82.57 | T11: ='Input AC Report '!AJ11 -> 2.1 | U11: ='Input AC Report '!AN11 -> 4063.85 | V11: ='Input AC Report '!AO11 -> 772.13 | W11: 19 | AA11: ='Input AC Report '!CI11 -> SIIX EMS MEXICO S. DE R.L. DE C.V.,San Luis Potosí | AB11: ='Input AC Report '!GX11 -> DE2329875-0024,DSV Air & Sea Germany GmbH - Westerkappeln | AC11: =_xlfn.IFNA(VLOOKUP('Input AC Report '!CU11,Validation!G:J,2,FALSE),"") -> Air | AD11: ='Input AC Report '!X11 -> DAP | AE11: ='Input AC Report '!V11 -> 1 | AF11: ='Input AC Report '!U11 -> PK | AG11: ='Input AC Report '!S11 -> 42 | AH11: ='Input AC Report '!T11 -> 46.1 | AI11: =_xlfn.IFNA(VLOOKUP('Input AC Report '!J11,Validation!J:K,2,FALSE),"") -> permanent import | AJ11: =MID('Input AC Report '!GX11,45,30) -> Westerkappeln | AK11: =MID('Input AC Report '!GP11,12,35) -> 000,HELLA GMBH & CO. KGAAUST | AM11: ='Input AC Report '!A11 -> SQRO0046448 | AN11: ='Input AC Report '!A11 -> SQRO0046448
A12: ='Input AC Report '!BL12 -> ATC400005670520252601/00001 | B12: ='Input AC Report '!G12 -> 1 | C12: ='Input AC Report '!GO12 -> DE2393166-0000,HELLA GMBH & CO. KGAAUST | D12: =LEFT(C12,9) -> DE2393166 | E12: =_xlfn.IFNA(VLOOKUP('Input AC Report '!DU12,Validation!A:B,2,FALSE),"") | F12: =_xlfn.IFNA(VLOOKUP('Input AC Report '!EQ12,Validation!A:B,2,FALSE),"") | G12: =_xlfn.IFNA(VLOOKUP('Input AC Report '!I12,Validation!D:E,2,FALSE),"") -> DUS | H12: =LEFT('Input AC Report '!I12,2) -> DE | I12: ='Input AC Report '!AS12 -> US | J12: ='Input AC Report '!AR12 -> US | K12: ='Input AC Report '!O12 -> 85122000900 | L12: ='Input AC Report '!N12 -> Heckleuchte für Kraftfahrzeuge | M12: ='Input AC Report '!AB12 -> 1583.52 | N12: ='Input AC Report '!W12 -> US-DE-JP-04242025 | O12: ='Input AC Report '!AD12 -> USD | P12: ='Input AC Report '!AE12 -> 1.1415 | Q12: ='Input AC Report '!AH12 -> 1330.98 | R12: ='Input AC Report '!AG12 -> USD | S12: ='Input AC Report '!AP12 -> 35.94 | T12: ='Input AC Report '!AJ12 -> 2.7 | U12: ='Input AC Report '!AN12 -> 1425.32 | V12: ='Input AC Report '!AO12 -> 270.81 | W12: 19 | AA12: ='Input AC Report '!CI12 -> Lucid USA Inc.,Newark,CA,94560,7373 Gateway Blvd., | AB12: ='Input AC Report '!GX12 -> DE2329875-0024,DSV Air & Sea Germany GmbH - Westerkappeln | AC12: =_xlfn.IFNA(VLOOKUP('Input AC Report '!CU12,Validation!G:J,2,FALSE),"") -> Air | AD12: ='Input AC Report '!X12 -> DAP | AE12: ='Input AC Report '!V12 -> 1 | AF12: ='Input AC Report '!U12 -> PK | AG12: ='Input AC Report '!S12 -> 27.2 | AH12: ='Input AC Report '!T12 -> 59 | AI12: =_xlfn.IFNA(VLOOKUP('Input AC Report '!J12,Validation!J:K,2,FALSE),"") -> permanent import | AJ12: =MID('Input AC Report '!GX12,45,30) -> Westerkappeln | AK12: =MID('Input AC Report '!GP12,12,35) -> 000,HELLA GMBH & CO. KGAAUST | AM12: ='Input AC Report '!A12 -> SSFO0157569 | AN12: ='Input AC Report '!A12 -> SSFO0157569
A13: ='Input AC Report '!BL13 -> ATC400087380520253302/00001 | B13: ='Input AC Report '!G13 -> 1 | C13: ='Input AC Report '!GO13 -> DE2393166-0000,HELLA GMBH & CO. KGAAUST | D13: =LEFT(C13,9) -> DE2393166 | E13: =_xlfn.IFNA(VLOOKUP('Input AC Report '!DU13,Validation!A:B,2,FALSE),"") | F13: =_xlfn.IFNA(VLOOKUP('Input AC Report '!EQ13,Validation!A:B,2,FALSE),"") | G13: =_xlfn.IFNA(VLOOKUP('Input AC Report '!I13,Validation!D:E,2,FALSE),"") -> FRA | H13: =LEFT('Input AC Report '!I13,2) -> DE | I13: ='Input AC Report '!AS13 -> CN | J13: ='Input AC Report '!AR13 -> CN | K13: ='Input AC Report '!O13 -> 90019000900 | L13: ='Input AC Report '!N13 -> Mikrolinsen-Arrays - Optikelement für Kfz | M13: ='Input AC Report '!AB13 -> 328185 | N13: ='Input AC Report '!W13 -> 0090009360 0090009361 0090009362 | O13: ='Input AC Report '!AD13 -> EUR | P13: ='Input AC Report '!AE13 -> 1 | Q13: ='Input AC Report '!AH13 -> 328402.59 | R13: ='Input AC Report '!AG13 -> CNY | S13: ='Input AC Report '!AP13 -> 0 | T13: ='Input AC Report '!AJ13 -> 0 | U13: ='Input AC Report '!AN13 -> 328693.69 | V13: ='Input AC Report '!AO13 -> 62451.8 | W13: 19 | AA13: ='Input AC Report '!CI13 -> Focuslight (Shaoguan) Optoelectronics Co.Ltd.,Shao | AB13: ='Input AC Report '!GX13 -> DE2329875-0024,DSV Air & Sea Germany GmbH - Westerkappeln | AC13: =_xlfn.IFNA(VLOOKUP('Input AC Report '!CU13,Validation!G:J,2,FALSE),"") -> Air | AD13: ='Input AC Report '!X13 -> DAP | AE13: ='Input AC Report '!V13 -> 1 | AF13: ='Input AC Report '!U13 -> PK | AG13: ='Input AC Report '!S13 -> 135.1 | AH13: ='Input AC Report '!T13 -> 156 | AI13: =_xlfn.IFNA(VLOOKUP('Input AC Report '!J13,Validation!J:K,2,FALSE),"") -> permanent import | AJ13: =MID('Input AC Report '!GX13,45,30) -> Westerkappeln | AK13: =MID('Input AC Report '!GP13,12,35) -> 000,HELLA GMBH & CO. KGAAUST | AM13: ='Input AC Report '!A13 -> SSZX71003019 | AN13: ='Input AC Report '!A13 -> SSZX71003019
A14: ='Input AC Report '!BL14 -> 0 | B14: ='Input AC Report '!G14 -> 0 | C14: ='Input AC Report '!GO14 -> 0 | D14: =LEFT(C14,9) -> 0 | E14: =_xlfn.IFNA(VLOOKUP('Input AC Report '!DU14,Validation!A:B,2,FALSE),"") | F14: =_xlfn.IFNA(VLOOKUP('Input AC Report '!EQ14,Validation!A:B,2,FALSE),"") | G14: =_xlfn.IFNA(VLOOKUP('Input AC Report '!I14,Validation!D:E,2,FALSE),"") | H14: =LEFT('Input AC Report '!I14,2) | I14: ='Input AC Report '!AS14 -> 0 | J14: ='Input AC Report '!AR14 -> 0 | K14: ='Input AC Report '!O14 -> 0 | L14: ='Input AC Report '!N14 -> 0 | M14: ='Input AC Report '!AB14 -> 0 | N14: ='Input AC Report '!W14 -> 0 | O14: ='Input AC Report '!AD14 -> 0 | P14: ='Input AC Report '!AE14 -> 0 | Q14: ='Input AC Report '!AH14 -> 0 | R14: ='Input AC Report '!AG14 -> 0 | S14: ='Input AC Report '!AP14 -> 0 | T14: ='Input AC Report '!AJ14 -> 0 | U14: ='Input AC Report '!AN14 -> 0 | V14: ='Input AC Report '!AO14 -> 0 | W14: 19 | AA14: ='Input AC Report '!CI14 -> 0 | AB14: ='Input AC Report '!GX14 -> 0 | AC14: =_xlfn.IFNA(VLOOKUP('Input AC Report '!CU14,Validation!G:J,2,FALSE),"") | AD14: ='Input AC Report '!X14 -> 0 | AE14: ='Input AC Report '!V14 -> 0 | AF14: ='Input AC Report '!U14 -> 0 | AG14: ='Input AC Report '!S14 -> 0 | AH14: ='Input AC Report '!T14 -> 0 | AI14: =_xlfn.IFNA(VLOOKUP('Input AC Report '!J14,Validation!J:K,2,FALSE),"") | AJ14: =MID('Input AC Report '!GX14,45,30) | AK14: =MID('Input AC Report '!GP14,12,35) | AM14: ='Input AC Report '!A14 -> 0 | AN14: ='Input AC Report '!A14 -> 0
A15: ='Input AC Report '!BL15 -> 0 | B15: ='Input AC Report '!G15 -> 0 | C15: ='Input AC Report '!GO15 -> 0 | D15: =LEFT(C15,9) -> 0 | E15: =_xlfn.IFNA(VLOOKUP('Input AC Report '!DU15,Validation!A:B,2,FALSE),"") | F15: =_xlfn.IFNA(VLOOKUP('Input AC Report '!EQ15,Validation!A:B,2,FALSE),"") | G15: =_xlfn.IFNA(VLOOKUP('Input AC Report '!I15,Validation!D:E,2,FALSE),"") | H15: =LEFT('Input AC Report '!I15,2) | I15: ='Input AC Report '!AS15 -> 0 | J15: ='Input AC Report '!AR15 -> 0 | K15: ='Input AC Report '!O15 -> 0 | L15: ='Input AC Report '!N15 -> 0 | M15: ='Input AC Report '!AB15 -> 0 | N15: ='Input AC Report '!W15 -> 0 | O15: ='Input AC Report '!AD15 -> 0 | P15: ='Input AC Report '!AE15 -> 0 | Q15: ='Input AC Report '!AH15 -> 0 | R15: ='Input AC Report '!AG15 -> 0 | S15: ='Input AC Report '!AP15 -> 0 | T15: ='Input AC Report '!AJ15 -> 0 | U15: ='Input AC Report '!AN15 -> 0 | V15: ='Input AC Report '!AO15 -> 0 | W15: 19 | AA15: ='Input AC Report '!CI15 -> 0 | AB15: ='Input AC Report '!GX15 -> 0 | AC15: =_xlfn.IFNA(VLOOKUP('Input AC Report '!CU15,Validation!G:J,2,FALSE),"") | AD15: ='Input AC Report '!X15 -> 0 | AE15: ='Input AC Report '!V15 -> 0 | AF15: ='Input AC Report '!U15 -> 0 | AG15: ='Input AC Report '!S15 -> 0 | AH15: ='Input AC Report '!T15 -> 0 | AI15: =_xlfn.IFNA(VLOOKUP('Input AC Report '!J15,Validation!J:K,2,FALSE),"") | AJ15: =MID('Input AC Report '!GX15,45,30) | AK15: =MID('Input AC Report '!GP15,12,35) | AM15: ='Input AC Report '!A15 -> 0 | AN15: ='Input AC Report '!A15 -> 0
A16: ='Input AC Report '!BL16 -> 0 | B16: ='Input AC Report '!G16 -> 0 | C16: ='Input AC Report '!GO16 -> 0 | D16: =LEFT(C16,9) -> 0 | E16: =_xlfn.IFNA(VLOOKUP('Input AC Report '!DU16,Validation!A:B,2,FALSE),"") | F16: =_xlfn.IFNA(VLOOKUP('Input AC Report '!EQ16,Validation!A:B,2,FALSE),"") | G16: =_xlfn.IFNA(VLOOKUP('Input AC Report '!I16,Validation!D:E,2,FALSE),"") | H16: =LEFT('Input AC Report '!I16,2) | I16: ='Input AC Report '!AS16 -> 0 | J16: ='Input AC Report '!AR16 -> 0 | K16: ='Input AC Report '!O16 -> 0 | L16: ='Input AC Report '!N16 -> 0 | M16: ='Input AC Report '!AB16 -> 0 | N16: ='Input AC Report '!W16 -> 0 | O16: ='Input AC Report '!AD16 -> 0 | P16: ='Input AC Report '!AE16 -> 0 | Q16: ='Input AC Report '!AH16 -> 0 | R16: ='Input AC Report '!AG16 -> 0 | S16: ='Input AC Report '!AP16 -> 0 | T16: ='Input AC Report '!AJ16 -> 0 | U16: ='Input AC Report '!AN16 -> 0 | V16: ='Input AC Report '!AO16 -> 0 | W16: 19 | AA16: ='Input AC Report '!CI16 -> 0 | AB16: ='Input AC Report '!GX16 -> 0 | AC16: =_xlfn.IFNA(VLOOKUP('Input AC Report '!CU16,Validation!G:J,2,FALSE),"") | AD16: ='Input AC Report '!X16 -> 0 | AE16: ='Input AC Report '!V16 -> 0 | AF16: ='Input AC Report '!U16 -> 0 | AG16: ='Input AC Report '!S16 -> 0 | AH16: ='Input AC Report '!T16 -> 0 | AI16: =_xlfn.IFNA(VLOOKUP('Input AC Report '!J16,Validation!J:K,2,FALSE),"") | AJ16: =MID('Input AC Report '!GX16,45,30) | AK16: =MID('Input AC Report '!GP16,12,35) | AM16: ='Input AC Report '!A16 -> 0 | AN16: ='Input AC Report '!A16 -> 0
A17: ='Input AC Report '!BL17 -> 0 | B17: ='Input AC Report '!G17 -> 0 | C17: ='Input AC Report '!GO17 -> 0 | D17: =LEFT(C17,9) -> 0 | E17: =_xlfn.IFNA(VLOOKUP('Input AC Report '!DU17,Validation!A:B,2,FALSE),"") | F17: =_xlfn.IFNA(VLOOKUP('Input AC Report '!EQ17,Validation!A:B,2,FALSE),"") | G17: =_xlfn.IFNA(VLOOKUP('Input AC Report '!I17,Validation!D:E,2,FALSE),"") | H17: =LEFT('Input AC Report '!I17,2) | I17: ='Input AC Report '!AS17 -> 0 | J17: ='Input AC Report '!AR17 -> 0 | K17: ='Input AC Report '!O17 -> 0 | L17: ='Input AC Report '!N17 -> 0 | M17: ='Input AC Report '!AB17 -> 0 | N17: ='Input AC Report '!W17 -> 0 | O17: ='Input AC Report '!AD17 -> 0 | P17: ='Input AC Report '!AE17 -> 0 | Q17: ='Input AC Report '!AH17 -> 0 | R17: ='Input AC Report '!AG17 -> 0 | S17: ='Input AC Report '!AP17 -> 0 | T17: ='Input AC Report '!AJ17 -> 0 | U17: ='Input AC Report '!AN17 -> 0 | V17: ='Input AC Report '!AO17 -> 0 | W17: 19 | AA17: ='Input AC Report '!CI17 -> 0 | AB17: ='Input AC Report '!GX17 -> 0 | AC17: =_xlfn.IFNA(VLOOKUP('Input AC Report '!CU17,Validation!G:J,2,FALSE),"") | AD17: ='Input AC Report '!X17 -> 0 | AE17: ='Input AC Report '!V17 -> 0 | AF17: ='Input AC Report '!U17 -> 0 | AG17: ='Input AC Report '!S17 -> 0 | AH17: ='Input AC Report '!T17 -> 0 | AI17: =_xlfn.IFNA(VLOOKUP('Input AC Report '!J17,Validation!J:K,2,FALSE),"") | AJ17: =MID('Input AC Report '!GX17,45,30) | AK17: =MID('Input AC Report '!GP17,12,35) | AM17: ='Input AC Report '!A17 -> 0 | AN17: ='Input AC Report '!A17 -> 0
A18: ='Input AC Report '!BL18 -> 0 | B18: ='Input AC Report '!G18 -> 0 | C18: ='Input AC Report '!GO18 -> 0 | D18: =LEFT(C18,9) -> 0 | E18: =_xlfn.IFNA(VLOOKUP('Input AC Report '!DU18,Validation!A:B,2,FALSE),"") | F18: =_xlfn.IFNA(VLOOKUP('Input AC Report '!EQ18,Validation!A:B,2,FALSE),"") | G18: =_xlfn.IFNA(VLOOKUP('Input AC Report '!I18,Validation!D:E,2,FALSE),"") | H18: =LEFT('Input AC Report '!I18,2) | I18: ='Input AC Report '!AS18 -> 0 | J18: ='Input AC Report '!AR18 -> 0 | K18: ='Input AC Report '!O18 -> 0 | L18: ='Input AC Report '!N18 -> 0 | M18: ='Input AC Report '!AB18 -> 0 | N18: ='Input AC Report '!W18 -> 0 | O18: ='Input AC Report '!AD18 -> 0 | P18: ='Input AC Report '!AE18 -> 0 | Q18: ='Input AC Report '!AH18 -> 0 | R18: ='Input AC Report '!AG18 -> 0 | S18: ='Input AC Report '!AP18 -> 0 | T18: ='Input AC Report '!AJ18 -> 0 | U18: ='Input AC Report '!AN18 -> 0 | V18: ='Input AC Report '!AO18 -> 0 | W18: 19 | AA18: ='Input AC Report '!CI18 -> 0 | AB18: ='Input AC Report '!GX18 -> 0 | AC18: =_xlfn.IFNA(VLOOKUP('Input AC Report '!CU18,Validation!G:J,2,FALSE),"") | AD18: ='Input AC Report '!X18 -> 0 | AE18: ='Input AC Report '!V18 -> 0 | AF18: ='Input AC Report '!U18 -> 0 | AG18: ='Input AC Report '!S18 -> 0 | AH18: ='Input AC Report '!T18 -> 0 | AI18: =_xlfn.IFNA(VLOOKUP('Input AC Report '!J18,Validation!J:K,2,FALSE),"") | AJ18: =MID('Input AC Report '!GX18,45,30) | AK18: =MID('Input AC Report '!GP18,12,35) | AM18: ='Input AC Report '!A18 -> 0 | AN18: ='Input AC Report '!A18 -> 0
A19: ='Input AC Report '!BL19 -> 0 | B19: ='Input AC Report '!G19 -> 0 | C19: ='Input AC Report '!GO19 -> 0 | D19: =LEFT(C19,9) -> 0 | E19: =_xlfn.IFNA(VLOOKUP('Input AC Report '!DU19,Validation!A:B,2,FALSE),"") | F19: =_xlfn.IFNA(VLOOKUP('Input AC Report '!EQ19,Validation!A:B,2,FALSE),"") | G19: =_xlfn.IFNA(VLOOKUP('Input AC Report '!I19,Validation!D:E,2,FALSE),"") | H19: =LEFT('Input AC Report '!I19,2) | I19: ='Input AC Report '!AS19 -> 0 | J19: ='Input AC Report '!AR19 -> 0 | K19: ='Input AC Report '!O19 -> 0 | L19: ='Input AC Report '!N19 -> 0 | M19: ='Input AC Report '!AB19 -> 0 | N19: ='Input AC Report '!W19 -> 0 | O19: ='Input AC Report '!AD19 -> 0 | P19: ='Input AC Report '!AE19 -> 0 | Q19: ='Input AC Report '!AH19 -> 0 | R19: ='Input AC Report '!AG19 -> 0 | S19: ='Input AC Report '!AP19 -> 0 | T19: ='Input AC Report '!AJ19 -> 0 | U19: ='Input AC Report '!AN19 -> 0 | V19: ='Input AC Report '!AO19 -> 0 | W19: 19 | AA19: ='Input AC Report '!CI19 -> 0 | AB19: ='Input AC Report '!GX19 -> 0 | AC19: =_xlfn.IFNA(VLOOKUP('Input AC Report '!CU19,Validation!G:J,2,FALSE),"") | AD19: ='Input AC Report '!X19 -> 0 | AE19: ='Input AC Report '!V19 -> 0 | AF19: ='Input AC Report '!U19 -> 0 | AG19: ='Input AC Report '!S19 -> 0 | AH19: ='Input AC Report '!T19 -> 0 | AI19: =_xlfn.IFNA(VLOOKUP('Input AC Report '!J19,Validation!J:K,2,FALSE),"") | AJ19: =MID('Input AC Report '!GX19,45,30) | AK19: =MID('Input AC Report '!GP19,12,35) | AM19: ='Input AC Report '!A19 -> 0 | AN19: ='Input AC Report '!A19 -> 0
... A28: ='Input AC Report '!BL28 -> 0 | B28: ='Input AC Report '!G28 -> 0 | C28: ='Input AC Report '!GO28 -> 0 | D28: =LEFT(C28,9) -> 0 | E28: =_xlfn.IFNA(VLOOKUP('Input AC Report '!DU28,Validation!A:B,2,FALSE),"") | F28: =_xlfn.IFNA(VLOOKUP('Input AC Report '!EQ28,Validation!A:B,2,FALSE),"") | G28: =_xlfn.IFNA(VLOOKUP('Input AC Report '!I28,Validation!D:E,2,FALSE),"") | H28: =LEFT('Input AC Report '!I28,2) | I28: ='Input AC Report '!AS28 -> 0 | J28: ='Input AC Report '!AR28 -> 0 | K28: ='Input AC Report '!O28 -> 0 | L28: ='Input AC Report '!N28 -> 0 | M28: ='Input AC Report '!AB28 -> 0 | N28: ='Input AC Report '!W28 -> 0 | O28: ='Input AC Report '!AD28 -> 0 | P28: ='Input AC Report '!AE28 -> 0 | Q28: ='Input AC Report '!AH28 -> 0 | R28: ='Input AC Report '!AG28 -> 0 | S28: ='Input AC Report '!AP28 -> 0 | T28: ='Input AC Report '!AJ28 -> 0 | U28: ='Input AC Report '!AN28 -> 0 | V28: ='Input AC Report '!AO28 -> 0 | W28: 19 | AA28: ='Input AC Report '!CI28 -> 0 | AB28: ='Input AC Report '!GX28 -> 0 | AC28: =_xlfn.IFNA(VLOOKUP('Input AC Report '!CU28,Validation!G:J,2,FALSE),"") | AD28: ='Input AC Report '!X28 -> 0 | AE28: ='Input AC Report '!V28 -> 0 | AF28: ='Input AC Report '!U28 -> 0 | AG28: ='Input AC Report '!S28 -> 0 | AH28: ='Input AC Report '!T28 -> 0 | AI28: =_xlfn.IFNA(VLOOKUP('Input AC Report '!J28,Validation!J:K,2,FALSE),"") | AJ28: =MID('Input AC Report '!GX28,45,30) | AK28: =MID('Input AC Report '!GP28,12,35) | AM28: ='Input AC Report '!A28 -> 0 | AN28: ='Input AC Report '!A28 -> 0
A29: ='Input AC Report '!BL29 -> 0 | B29: ='Input AC Report '!G29 -> 0 | C29: ='Input AC Report '!GO29 -> 0 | D29: =LEFT(C29,9) -> 0 | E29: =_xlfn.IFNA(VLOOKUP('Input AC Report '!DU29,Validation!A:B,2,FALSE),"") | F29: =_xlfn.IFNA(VLOOKUP('Input AC Report '!EQ29,Validation!A:B,2,FALSE),"") | G29: =_xlfn.IFNA(VLOOKUP('Input AC Report '!I29,Validation!D:E,2,FALSE),"") | H29: =LEFT('Input AC Report '!I29,2) | I29: ='Input AC Report '!AS29 -> 0 | J29: ='Input AC Report '!AR29 -> 0 | K29: ='Input AC Report '!O29 -> 0 | L29: ='Input AC Report '!N29 -> 0 | M29: ='Input AC Report '!AB29 -> 0 | N29: ='Input AC Report '!W29 -> 0 | O29: ='Input AC Report '!AD29 -> 0 | P29: ='Input AC Report '!AE29 -> 0 | Q29: ='Input AC Report '!AH29 -> 0 | R29: ='Input AC Report '!AG29 -> 0 | S29: ='Input AC Report '!AP29 -> 0 | T29: ='Input AC Report '!AJ29 -> 0 | U29: ='Input AC Report '!AN29 -> 0 | V29: ='Input AC Report '!AO29 -> 0 | AA29: ='Input AC Report '!CI29 -> 0 | AB29: ='Input AC Report '!GX29 -> 0 | AC29: =_xlfn.IFNA(VLOOKUP('Input AC Report '!CU29,Validation!G:J,2,FALSE),"") | AD29: ='Input AC Report '!X29 -> 0 | AE29: ='Input AC Report '!V29 -> 0 | AF29: ='Input AC Report '!U29 -> 0 | AG29: ='Input AC Report '!S29 -> 0 | AH29: ='Input AC Report '!T29 -> 0 | AI29: =_xlfn.IFNA(VLOOKUP('Input AC Report '!J29,Validation!J:K,2,FALSE),"") | AJ29: =MID('Input AC Report '!GX29,45,30) | AK29: =MID('Input AC Report '!GP29,12,35) | AM29: ='Input AC Report '!A29 -> 0 | AN29: ='Input AC Report '!A29 -> 0
A30: ='Input AC Report '!BL30 -> 0 | B30: ='Input AC Report '!G30 -> 0 | C30: ='Input AC Report '!GO30 -> 0 | D30: =LEFT(C30,9) -> 0 | E30: =_xlfn.IFNA(VLOOKUP('Input AC Report '!DU30,Validation!A:B,2,FALSE),"") | F30: =_xlfn.IFNA(VLOOKUP('Input AC Report '!EQ30,Validation!A:B,2,FALSE),"") | G30: =_xlfn.IFNA(VLOOKUP('Input AC Report '!I30,Validation!D:E,2,FALSE),"") | H30: =LEFT('Input AC Report '!I30,2) | I30: ='Input AC Report '!AS30 -> 0 | J30: ='Input AC Report '!AR30 -> 0 | K30: ='Input AC Report '!O30 -> 0 | L30: ='Input AC Report '!N30 -> 0 | M30: ='Input AC Report '!AB30 -> 0 | N30: ='Input AC Report '!W30 -> 0 | O30: ='Input AC Report '!AD30 -> 0 | P30: ='Input AC Report '!AE30 -> 0 | Q30: ='Input AC Report '!AH30 -> 0 | R30: ='Input AC Report '!AG30 -> 0 | S30: ='Input AC Report '!AP30 -> 0 | T30: ='Input AC Report '!AJ30 -> 0 | U30: ='Input AC Report '!AN30 -> 0 | V30: ='Input AC Report '!AO30 -> 0 | AA30: ='Input AC Report '!CI30 -> 0 | AB30: ='Input AC Report '!GX30 -> 0 | AC30: =_xlfn.IFNA(VLOOKUP('Input AC Report '!CU30,Validation!G:J,2,FALSE),"") | AD30: ='Input AC Report '!X30 -> 0 | AE30: ='Input AC Report '!V30 -> 0 | AF30: ='Input AC Report '!U30 -> 0 | AG30: ='Input AC Report '!S30 -> 0 | AH30: ='Input AC Report '!T30 -> 0 | AI30: =_xlfn.IFNA(VLOOKUP('Input AC Report '!J30,Validation!J:K,2,FALSE),"") | AJ30: =MID('Input AC Report '!GX30,45,30) | AK30: =MID('Input AC Report '!GP30,12,35) | AM30: ='Input AC Report '!A30 -> 0 | AN30: ='Input AC Report '!A30 -> 0
A31: ='Input AC Report '!BL31 -> 0 | B31: ='Input AC Report '!G31 -> 0 | C31: ='Input AC Report '!GO31 -> 0 | D31: =LEFT(C31,9) -> 0 | E31: =_xlfn.IFNA(VLOOKUP('Input AC Report '!DU31,Validation!A:B,2,FALSE),"") | F31: =_xlfn.IFNA(VLOOKUP('Input AC Report '!EQ31,Validation!A:B,2,FALSE),"") | G31: =_xlfn.IFNA(VLOOKUP('Input AC Report '!I31,Validation!D:E,2,FALSE),"") | H31: =LEFT('Input AC Report '!I31,2) | I31: ='Input AC Report '!AS31 -> 0 | J31: ='Input AC Report '!AR31 -> 0 | K31: ='Input AC Report '!O31 -> 0 | L31: ='Input AC Report '!N31 -> 0 | M31: ='Input AC Report '!AB31 -> 0 | N31: ='Input AC Report '!W31 -> 0 | O31: ='Input AC Report '!AD31 -> 0 | P31: ='Input AC Report '!AE31 -> 0 | Q31: ='Input AC Report '!AH31 -> 0 | R31: ='Input AC Report '!AG31 -> 0 | S31: ='Input AC Report '!AP31 -> 0 | T31: ='Input AC Report '!AJ31 -> 0 | U31: ='Input AC Report '!AN31 -> 0 | V31: ='Input AC Report '!AO31 -> 0 | AA31: ='Input AC Report '!CI31 -> 0 | AB31: ='Input AC Report '!GX31 -> 0 | AC31: =_xlfn.IFNA(VLOOKUP('Input AC Report '!CU31,Validation!G:J,2,FALSE),"") | AD31: ='Input AC Report '!X31 -> 0 | AE31: ='Input AC Report '!V31 -> 0 | AF31: ='Input AC Report '!U31 -> 0 | AG31: ='Input AC Report '!S31 -> 0 | AH31: ='Input AC Report '!T31 -> 0 | AI31: =_xlfn.IFNA(VLOOKUP('Input AC Report '!J31,Validation!J:K,2,FALSE),"") | AJ31: =MID('Input AC Report '!GX31,45,30) | AK31: =MID('Input AC Report '!GP31,12,35) | AM31: ='Input AC Report '!A31 -> 0 | AN31: ='Input AC Report '!A31 -> 0
A32: ='Input AC Report '!BL32 -> 0 | B32: ='Input AC Report '!G32 -> 0 | C32: ='Input AC Report '!GO32 -> 0 | D32: =LEFT(C32,9) -> 0 | E32: =_xlfn.IFNA(VLOOKUP('Input AC Report '!DU32,Validation!A:B,2,FALSE),"") | F32: =_xlfn.IFNA(VLOOKUP('Input AC Report '!EQ32,Validation!A:B,2,FALSE),"") | G32: =_xlfn.IFNA(VLOOKUP('Input AC Report '!I32,Validation!D:E,2,FALSE),"") | H32: =LEFT('Input AC Report '!I32,2) | I32: ='Input AC Report '!AS32 -> 0 | J32: ='Input AC Report '!AR32 -> 0 | K32: ='Input AC Report '!O32 -> 0 | L32: ='Input AC Report '!N32 -> 0 | M32: ='Input AC Report '!AB32 -> 0 | N32: ='Input AC Report '!W32 -> 0 | O32: ='Input AC Report '!AD32 -> 0 | P32: ='Input AC Report '!AE32 -> 0 | Q32: ='Input AC Report '!AH32 -> 0 | R32: ='Input AC Report '!AG32 -> 0 | S32: ='Input AC Report '!AP32 -> 0 | T32: ='Input AC Report '!AJ32 -> 0 | U32: ='Input AC Report '!AN32 -> 0 | V32: ='Input AC Report '!AO32 -> 0 | AA32: ='Input AC Report '!CI32 -> 0 | AB32: ='Input AC Report '!GX32 -> 0 | AC32: =_xlfn.IFNA(VLOOKUP('Input AC Report '!CU32,Validation!G:J,2,FALSE),"") | AD32: ='Input AC Report '!X32 -> 0 | AE32: ='Input AC Report '!V32 -> 0 | AF32: ='Input AC Report '!U32 -> 0 | AG32: ='Input AC Report '!S32 -> 0 | AH32: ='Input AC Report '!T32 -> 0 | AI32: =_xlfn.IFNA(VLOOKUP('Input AC Report '!J32,Validation!J:K,2,FALSE),"") | AJ32: =MID('Input AC Report '!GX32,45,30) | AK32: =MID('Input AC Report '!GP32,12,35) | AM32: ='Input AC Report '!A32 -> 0 | AN32: ='Input AC Report '!A32 -> 0
A33: ='Input AC Report '!BL33 -> 0 | B33: ='Input AC Report '!G33 -> 0 | C33: ='Input AC Report '!GO33 -> 0 | D33: =LEFT(C33,9) -> 0 | E33: =_xlfn.IFNA(VLOOKUP('Input AC Report '!DU33,Validation!A:B,2,FALSE),"") | F33: =_xlfn.IFNA(VLOOKUP('Input AC Report '!EQ33,Validation!A:B,2,FALSE),"") | G33: =_xlfn.IFNA(VLOOKUP('Input AC Report '!I33,Validation!D:E,2,FALSE),"") | H33: =LEFT('Input AC Report '!I33,2) | I33: ='Input AC Report '!AS33 -> 0 | J33: ='Input AC Report '!AR33 -> 0 | K33: ='Input AC Report '!O33 -> 0 | L33: ='Input AC Report '!N33 -> 0 | M33: ='Input AC Report '!AB33 -> 0 | N33: ='Input AC Report '!W33 -> 0 | O33: ='Input AC Report '!AD33 -> 0 | P33: ='Input AC Report '!AE33 -> 0 | Q33: ='Input AC Report '!AH33 -> 0 | R33: ='Input AC Report '!AG33 -> 0 | S33: ='Input AC Report '!AP33 -> 0 | T33: ='Input AC Report '!AJ33 -> 0 | U33: ='Input AC Report '!AN33 -> 0 | V33: ='Input AC Report '!AO33 -> 0 | AA33: ='Input AC Report '!CI33 -> 0 | AB33: ='Input AC Report '!GX33 -> 0 | AC33: =_xlfn.IFNA(VLOOKUP('Input AC Report '!CU33,Validation!G:J,2,FALSE),"") | AD33: ='Input AC Report '!X33 -> 0 | AE33: ='Input AC Report '!V33 -> 0 | AF33: ='Input AC Report '!U33 -> 0 | AG33: ='Input AC Report '!S33 -> 0 | AH33: ='Input AC Report '!T33 -> 0 | AI33: =_xlfn.IFNA(VLOOKUP('Input AC Report '!J33,Validation!J:K,2,FALSE),"") | AJ33: =MID('Input AC Report '!GX33,45,30) | AK33: =MID('Input AC Report '!GP33,12,35) | AM33: ='Input AC Report '!A33 -> 0 | AN33: ='Input AC Report '!A33 -> 0
A34: ='Input AC Report '!BL34 -> 0 | B34: ='Input AC Report '!G34 -> 0 | C34: ='Input AC Report '!GO34 -> 0 | D34: =LEFT(C34,9) -> 0 | E34: =_xlfn.IFNA(VLOOKUP('Input AC Report '!DU34,Validation!A:B,2,FALSE),"") | F34: =_xlfn.IFNA(VLOOKUP('Input AC Report '!EQ34,Validation!A:B,2,FALSE),"") | G34: =_xlfn.IFNA(VLOOKUP('Input AC Report '!I34,Validation!D:E,2,FALSE),"") | H34: =LEFT('Input AC Report '!I34,2) | I34: ='Input AC Report '!AS34 -> 0 | J34: ='Input AC Report '!AR34 -> 0 | K34: ='Input AC Report '!O34 -> 0 | L34: ='Input AC Report '!N34 -> 0 | M34: ='Input AC Report '!AB34 -> 0 | N34: ='Input AC Report '!W34 -> 0 | O34: ='Input AC Report '!AD34 -> 0 | P34: ='Input AC Report '!AE34 -> 0 | Q34: ='Input AC Report '!AH34 -> 0 | R34: ='Input AC Report '!AG34 -> 0 | S34: ='Input AC Report '!AP34 -> 0 | T34: ='Input AC Report '!AJ34 -> 0 | U34: ='Input AC Report '!AN34 -> 0 | V34: ='Input AC Report '!AO34 -> 0 | AA34: ='Input AC Report '!CI34 -> 0 | AB34: ='Input AC Report '!GX34 -> 0 | AC34: =_xlfn.IFNA(VLOOKUP('Input AC Report '!CU34,Validation!G:J,2,FALSE),"") | AD34: ='Input AC Report '!X34 -> 0 | AE34: ='Input AC Report '!V34 -> 0 | AF34: ='Input AC Report '!U34 -> 0 | AG34: ='Input AC Report '!S34 -> 0 | AH34: ='Input AC Report '!T34 -> 0 | AI34: =_xlfn.IFNA(VLOOKUP('Input AC Report '!J34,Validation!J:K,2,FALSE),"") | AJ34: =MID('Input AC Report '!GX34,45,30) | AK34: =MID('Input AC Report '!GP34,12,35) | AM34: ='Input AC Report '!A34 -> 0 | AN34: ='Input AC Report '!A34 -> 0
A35: ='Input AC Report '!BL35 -> 0 | B35: ='Input AC Report '!G35 -> 0 | C35: ='Input AC Report '!GO35 -> 0 | D35: =LEFT(C35,9) -> 0 | E35: =_xlfn.IFNA(VLOOKUP('Input AC Report '!DU35,Validation!A:B,2,FALSE),"") | F35: =_xlfn.IFNA(VLOOKUP('Input AC Report '!EQ35,Validation!A:B,2,FALSE),"") | G35: =_xlfn.IFNA(VLOOKUP('Input AC Report '!I35,Validation!D:E,2,FALSE),"") | H35: =LEFT('Input AC Report '!I35,2) | I35: ='Input AC Report '!AS35 -> 0 | J35: ='Input AC Report '!AR35 -> 0 | K35: ='Input AC Report '!O35 -> 0 | L35: ='Input AC Report '!N35 -> 0 | M35: ='Input AC Report '!AB35 -> 0 | N35: ='Input AC Report '!W35 -> 0 | O35: ='Input AC Report '!AD35 -> 0 | P35: ='Input AC Report '!AE35 -> 0 | Q35: ='Input AC Report '!AH35 -> 0 | R35: ='Input AC Report '!AG35 -> 0 | S35: ='Input AC Report '!AP35 -> 0 | T35: ='Input AC Report '!AJ35 -> 0 | U35: ='Input AC Report '!AN35 -> 0 | V35: ='Input AC Report '!AO35 -> 0 | AA35: ='Input AC Report '!CI35 -> 0 | AB35: ='Input AC Report '!GX35 -> 0 | AC35: =_xlfn.IFNA(VLOOKUP('Input AC Report '!CU35,Validation!G:J,2,FALSE),"") | AD35: ='Input AC Report '!X35 -> 0 | AE35: ='Input AC Report '!V35 -> 0 | AF35: ='Input AC Report '!U35 -> 0 | AG35: ='Input AC Report '!S35 -> 0 | AH35: ='Input AC Report '!T35 -> 0 | AI35: =_xlfn.IFNA(VLOOKUP('Input AC Report '!J35,Validation!J:K,2,FALSE),"") | AJ35: =MID('Input AC Report '!GX35,45,30) | AK35: =MID('Input AC Report '!GP35,12,35) | AM35: ='Input AC Report '!A35 -> 0 | AN35: ='Input AC Report '!A35 -> 0
A36: ='Input AC Report '!BL36 -> 0 | B36: ='Input AC Report '!G36 -> 0 | C36: ='Input AC Report '!GO36 -> 0 | D36: =LEFT(C36,9) -> 0 | E36: =_xlfn.IFNA(VLOOKUP('Input AC Report '!DU36,Validation!A:B,2,FALSE),"") | F36: =_xlfn.IFNA(VLOOKUP('Input AC Report '!EQ36,Validation!A:B,2,FALSE),"") | G36: =_xlfn.IFNA(VLOOKUP('Input AC Report '!I36,Validation!D:E,2,FALSE),"") | H36: =LEFT('Input AC Report '!I36,2) | I36: ='Input AC Report '!AS36 -> 0 | J36: ='Input AC Report '!AR36 -> 0 | K36: ='Input AC Report '!O36 -> 0 | L36: ='Input AC Report '!N36 -> 0 | M36: ='Input AC Report '!AB36 -> 0 | N36: ='Input AC Report '!W36 -> 0 | O36: ='Input AC Report '!AD36 -> 0 | P36: ='Input AC Report '!AE36 -> 0 | Q36: ='Input AC Report '!AH36 -> 0 | R36: ='Input AC Report '!AG36 -> 0 | S36: ='Input AC Report '!AP36 -> 0 | T36: ='Input AC Report '!AJ36 -> 0 | U36: ='Input AC Report '!AN36 -> 0 | V36: ='Input AC Report '!AO36 -> 0 | AA36: ='Input AC Report '!CI36 -> 0 | AB36: ='Input AC Report '!GX36 -> 0 | AC36: =_xlfn.IFNA(VLOOKUP('Input AC Report '!CU36,Validation!G:J,2,FALSE),"") | AD36: ='Input AC Report '!X36 -> 0 | AE36: ='Input AC Report '!V36 -> 0 | AF36: ='Input AC Report '!U36 -> 0 | AG36: ='Input AC Report '!S36 -> 0 | AH36: ='Input AC Report '!T36 -> 0 | AI36: =_xlfn.IFNA(VLOOKUP('Input AC Report '!J36,Validation!J:K,2,FALSE),"") | AJ36: =MID('Input AC Report '!GX36,45,30) | AK36: =MID('Input AC Report '!GP36,12,35) | AM36: ='Input AC Report '!A36 -> 0 | AN36: ='Input AC Report '!A36 -> 0
A37: ='Input AC Report '!BL37 -> 0 | B37: ='Input AC Report '!G37 -> 0 | C37: ='Input AC Report '!GO37 -> 0 | D37: =LEFT(C37,9) -> 0 | E37: =_xlfn.IFNA(VLOOKUP('Input AC Report '!DU37,Validation!A:B,2,FALSE),"") | F37: =_xlfn.IFNA(VLOOKUP('Input AC Report '!EQ37,Validation!A:B,2,FALSE),"") | G37: =_xlfn.IFNA(VLOOKUP('Input AC Report '!I37,Validation!D:E,2,FALSE),"") | H37: =LEFT('Input AC Report '!I37,2) | I37: ='Input AC Report '!AS37 -> 0 | J37: ='Input AC Report '!AR37 -> 0 | K37: ='Input AC Report '!O37 -> 0 | L37: ='Input AC Report '!N37 -> 0 | M37: ='Input AC Report '!AB37 -> 0 | N37: ='Input AC Report '!W37 -> 0 | O37: ='Input AC Report '!AD37 -> 0 | P37: ='Input AC Report '!AE37 -> 0 | Q37: ='Input AC Report '!AH37 -> 0 | R37: ='Input AC Report '!AG37 -> 0 | S37: ='Input AC Report '!AP37 -> 0 | T37: ='Input AC Report '!AJ37 -> 0 | U37: ='Input AC Report '!AN37 -> 0 | V37: ='Input AC Report '!AO37 -> 0 | AA37: ='Input AC Report '!CI37 -> 0 | AB37: ='Input AC Report '!GX37 -> 0 | AC37: =_xlfn.IFNA(VLOOKUP('Input AC Report '!CU37,Validation!G:J,2,FALSE),"") | AD37: ='Input AC Report '!X37 -> 0 | AE37: ='Input AC Report '!V37 -> 0 | AF37: ='Input AC Report '!U37 -> 0 | AG37: ='Input AC Report '!S37 -> 0 | AH37: ='Input AC Report '!T37 -> 0 | AI37: =_xlfn.IFNA(VLOOKUP('Input AC Report '!J37,Validation!J:K,2,FALSE),"") | AJ37: =MID('Input AC Report '!GX37,45,30) | AK37: =MID('Input AC Report '!GP37,12,35) | AM37: ='Input AC Report '!A37 -> 0 | AN37: ='Input AC Report '!A37 -> 0
A38: ='Input AC Report '!BL38 -> 0 | B38: ='Input AC Report '!G38 -> 0 | C38: ='Input AC Report '!GO38 -> 0 | D38: =LEFT(C38,9) -> 0 | E38: =_xlfn.IFNA(VLOOKUP('Input AC Report '!DU38,Validation!A:B,2,FALSE),"") | F38: =_xlfn.IFNA(VLOOKUP('Input AC Report '!EQ38,Validation!A:B,2,FALSE),"") | G38: =_xlfn.IFNA(VLOOKUP('Input AC Report '!I38,Validation!D:E,2,FALSE),"") | H38: =LEFT('Input AC Report '!I38,2) | I38: ='Input AC Report '!AS38 -> 0 | J38: ='Input AC Report '!AR38 -> 0 | K38: ='Input AC Report '!O38 -> 0 | L38: ='Input AC Report '!N38 -> 0 | M38: ='Input AC Report '!AB38 -> 0 | N38: ='Input AC Report '!W38 -> 0 | O38: ='Input AC Report '!AD38 -> 0 | P38: ='Input AC Report '!AE38 -> 0 | Q38: ='Input AC Report '!AH38 -> 0 | R38: ='Input AC Report '!AG38 -> 0 | S38: ='Input AC Report '!AP38 -> 0 | T38: ='Input AC Report '!AJ38 -> 0 | U38: ='Input AC Report '!AN38 -> 0 | V38: ='Input AC Report '!AO38 -> 0 | AA38: ='Input AC Report '!CI38 -> 0 | AB38: ='Input AC Report '!GX38 -> 0 | AC38: =_xlfn.IFNA(VLOOKUP('Input AC Report '!CU38,Validation!G:J,2,FALSE),"") | AD38: ='Input AC Report '!X38 -> 0 | AE38: ='Input AC Report '!V38 -> 0 | AF38: ='Input AC Report '!U38 -> 0 | AG38: ='Input AC Report '!S38 -> 0 | AH38: ='Input AC Report '!T38 -> 0 | AI38: =_xlfn.IFNA(VLOOKUP('Input AC Report '!J38,Validation!J:K,2,FALSE),"") | AJ38: =MID('Input AC Report '!GX38,45,30) | AK38: =MID('Input AC Report '!GP38,12,35) | AM38: ='Input AC Report '!A38 -> 0 | AN38: ='Input AC Report '!A38 -> 0
A39: ='Input AC Report '!BL39 -> 0 | B39: ='Input AC Report '!G39 -> 0 | C39: ='Input AC Report '!GO39 -> 0 | D39: =LEFT(C39,9) -> 0 | E39: =_xlfn.IFNA(VLOOKUP('Input AC Report '!DU39,Validation!A:B,2,FALSE),"") | F39: =_xlfn.IFNA(VLOOKUP('Input AC Report '!EQ39,Validation!A:B,2,FALSE),"") | G39: =_xlfn.IFNA(VLOOKUP('Input AC Report '!I39,Validation!D:E,2,FALSE),"") | H39: =LEFT('Input AC Report '!I39,2) | I39: ='Input AC Report '!AS39 -> 0 | J39: ='Input AC Report '!AR39 -> 0 | K39: ='Input AC Report '!O39 -> 0 | L39: ='Input AC Report '!N39 -> 0 | M39: ='Input AC Report '!AB39 -> 0 | N39: ='Input AC Report '!W39 -> 0 | O39: ='Input AC Report '!AD39 -> 0 | P39: ='Input AC Report '!AE39 -> 0 | Q39: ='Input AC Report '!AH39 -> 0 | R39: ='Input AC Report '!AG39 -> 0 | S39: ='Input AC Report '!AP39 -> 0 | T39: ='Input AC Report '!AJ39 -> 0 | U39: ='Input AC Report '!AN39 -> 0 | V39: ='Input AC Report '!AO39 -> 0 | AA39: ='Input AC Report '!CI39 -> 0 | AB39: ='Input AC Report '!GX39 -> 0 | AC39: =_xlfn.IFNA(VLOOKUP('Input AC Report '!CU39,Validation!G:J,2,FALSE),"") | AD39: ='Input AC Report '!X39 -> 0 | AE39: ='Input AC Report '!V39 -> 0 | AF39: ='Input AC Report '!U39 -> 0 | AG39: ='Input AC Report '!S39 -> 0 | AH39: ='Input AC Report '!T39 -> 0 | AI39: =_xlfn.IFNA(VLOOKUP('Input AC Report '!J39,Validation!J:K,2,FALSE),"") | AJ39: =MID('Input AC Report '!GX39,45,30) | AK39: =MID('Input AC Report '!GP39,12,35) | AM39: ='Input AC Report '!A39 -> 0 | AN39: ='Input AC Report '!A39 -> 0
A40: ='Input AC Report '!BL40 -> 0 | B40: ='Input AC Report '!G40 -> 0 | C40: ='Input AC Report '!GO40 -> 0 | D40: =LEFT(C40,9) -> 0 | E40: =_xlfn.IFNA(VLOOKUP('Input AC Report '!DU40,Validation!A:B,2,FALSE),"") | F40: =_xlfn.IFNA(VLOOKUP('Input AC Report '!EQ40,Validation!A:B,2,FALSE),"") | G40: =_xlfn.IFNA(VLOOKUP('Input AC Report '!I40,Validation!D:E,2,FALSE),"") | H40: =LEFT('Input AC Report '!I40,2) | I40: ='Input AC Report '!AS40 -> 0 | J40: ='Input AC Report '!AR40 -> 0 | K40: ='Input AC Report '!O40 -> 0 | L40: ='Input AC Report '!N40 -> 0 | M40: ='Input AC Report '!AB40 -> 0 | N40: ='Input AC Report '!W40 -> 0 | O40: ='Input AC Report '!AD40 -> 0 | P40: ='Input AC Report '!AE40 -> 0 | Q40: ='Input AC Report '!AH40 -> 0 | R40: ='Input AC Report '!AG40 -> 0 | S40: ='Input AC Report '!AP40 -> 0 | T40: ='Input AC Report '!AJ40 -> 0 | U40: ='Input AC Report '!AN40 -> 0 | V40: ='Input AC Report '!AO40 -> 0 | AA40: ='Input AC Report '!CI40 -> 0 | AB40: ='Input AC Report '!GX40 -> 0 | AC40: =_xlfn.IFNA(VLOOKUP('Input AC Report '!CU40,Validation!G:J,2,FALSE),"") | AD40: ='Input AC Report '!X40 -> 0 | AE40: ='Input AC Report '!V40 -> 0 | AF40: ='Input AC Report '!U40 -> 0 | AG40: ='Input AC Report '!S40 -> 0 | AH40: ='Input AC Report '!T40 -> 0 | AI40: =_xlfn.IFNA(VLOOKUP('Input AC Report '!J40,Validation!J:K,2,FALSE),"") | AJ40: =MID('Input AC Report '!GX40,45,30) | AK40: =MID('Input AC Report '!GP40,12,35) | AM40: ='Input AC Report '!A40 -> 0 | AN40: ='Input AC Report '!A40 -> 0
... A54: ='Input AC Report '!BL54 -> 0 | B54: ='Input AC Report '!G54 -> 0 | C54: ='Input AC Report '!GO54 -> 0 | D54: =LEFT(C54,9) -> 0 | E54: =_xlfn.IFNA(VLOOKUP('Input AC Report '!DU54,Validation!A:B,2,FALSE),"") | F54: =_xlfn.IFNA(VLOOKUP('Input AC Report '!EQ54,Validation!A:B,2,FALSE),"") | G54: =_xlfn.IFNA(VLOOKUP('Input AC Report '!I54,Validation!D:E,2,FALSE),"") | H54: =LEFT('Input AC Report '!I54,2) | I54: ='Input AC Report '!AS54 -> 0 | J54: ='Input AC Report '!AR54 -> 0 | K54: ='Input AC Report '!O54 -> 0 | L54: ='Input AC Report '!N54 -> 0 | M54: ='Input AC Report '!AB54 -> 0 | N54: ='Input AC Report '!W54 -> 0 | O54: ='Input AC Report '!AD54 -> 0 | P54: ='Input AC Report '!AE54 -> 0 | Q54: ='Input AC Report '!AH54 -> 0 | R54: ='Input AC Report '!AG54 -> 0 | S54: ='Input AC Report '!AP54 -> 0 | T54: ='Input AC Report '!AJ54 -> 0 | U54: ='Input AC Report '!AN54 -> 0 | V54: ='Input AC Report '!AO54 -> 0 | AA54: ='Input AC Report '!CI54 -> 0 | AB54: ='Input AC Report '!GX54 -> 0 | AC54: =_xlfn.IFNA(VLOOKUP('Input AC Report '!CU54,Validation!G:J,2,FALSE),"") | AD54: ='Input AC Report '!X54 -> 0 | AE54: ='Input AC Report '!V54 -> 0 | AF54: ='Input AC Report '!U54 -> 0 | AG54: ='Input AC Report '!S54 -> 0 | AH54: ='Input AC Report '!T54 -> 0 | AI54: =_xlfn.IFNA(VLOOKUP('Input AC Report '!J54,Validation!J:K,2,FALSE),"") | AJ54: =MID('Input AC Report '!GX54,45,30) | AK54: =MID('Input AC Report '!GP54,12,35) | AM54: ='Input AC Report '!A54 -> 0 | AN54: ='Input AC Report '!A54 -> 0

Sheet Data Fields
A1: Field | B1: Import Report | C1: Description | D1: Format required
A2: 1 | B2: Formal Entry Number | C2: Import declaration number | D2: Text
A3: 2 | B3: Line No | C3: Declaration including multiple lines | D3: Text
A4: 3 | B4: Importer Name | C4: Entity that is the importer of the goods | D4: Text
A5: 3.1 | B5: EORI Number / Tax ID / Equivalent | C5: EORI. Economic Operators Registration and Identification number. Businesses identification number in all customs procedures | D5: Text
A6: 4 | B6: Arrival Date | C6: The date imported goods entered the country of import | D6: Date
A7: 5 | B7: Entry Date (ddmmyy) | C7: The date the goods were customs cleared by Customs | D7: Date
A8: 6 | B8: Port of Entry | C8: Local port where goods are imported | D8: Text
A9: 7 | B9: Declaration Country | C9: The country where the goods are entered into free circulation / placed under customs procedure | D9: Text
A10: 8 | B10: Country of Origin | C10: The country where the imported goods originated | D10: Text
A11: 9 | B11: Shipping Country | C11: The country where the goods are exported from (country of export) | D11: Text
A12: 10 | B12: HTS Code (Tariff Number) | C12: The classification code assigned to the imported product (HTS code) | D12: Text
A13: 11 | B13: Item Description | C13: The general description of the imported product (Product / Item description) | D13: Text
... A46: 44 | B46: [Placeholder] | C46: Please place any additional fields not covered by the above in columns 35 and further | D46: TBD
A48: *Please replace VAT and other fees/taxes with the applicable indirect tax(es) paid upon import in your country
A49: * CBAM Fields must be considered only for the EMA Region.
A51: Version | B51: Date | C51: Description of the change | D51: Additional Comments
A52: 1 | B52: 45243 | C52: Initial version
A53: 2 | B53: 45261 | C53: Adjustment to the fields by EY.

Sheet Input AC Report 
